Workbook

Sheet Поступления
A1: категории поступлений | B1: Продажи текущие | C1: Продажи контракт | D1: Спецпроект | E1: Кредит | F1: Возвраты от поставщиков | G1: Нераспределенное | H1: Прочие поступл. от фин. операций
A2: подкатегории | B2: КИВИ Кейтеринг | C2: ЯРОД (контракт) | D2: Строители Олонхо
B3: КИВИ Ивент | C3: РБ2 (контракт) | D3: Кобяйская СОШ (лагерь)
B4: КИВИ Деливери | C4: Школа №7 (контракт) | D4: Прочие спецпроекты
B5: КИВИ фит | C5: Школа №21 (контракт)
B6: РЦ буфет | C6: Школа №26 (контракт)
B7: РСКШИ буфет | C7: Айыы кыьата (контракт)
B8: Речевая буфет | C8: Речевая (контракт)
B9: Кытылга | C9: РЦ (контракт)
B10: Школа №7 | C10: РСКШИ (контракт)
B11: Школа №21 | C11: ДИКБ (контракт)
B12: Школа №26
B13: Айыы кыьата
B14: Дебиторская задолженность покупателей

Sheet Расходы
A1: Группы
A2: Обязательные
B3: Прочие | C3: Банк | D3: Налог | E3: Помещения | F3: Транспорт
B4: Агентские вознаграждения | C4: Банковское обслуживание | D4: Налог на доходы | E4: Оплата аренды и ВКУ | F4: Топливо
B5: Агрегаторы | C5: Комиссия по эквайрингу | D5: Налог ФОТ | E5: Услуги связи и интернета | F5: Услуги такси/Развоз персонала
B6: Расходы на программное обеспечение | C6: Погашение кредитов
A7: Переменные
B8: Рекламный бюджет | C8: Себестоимость | D8: Кредиторка | E8: Вывод прибыли (дивиденды) | F8: Возврат клиентам | G8: Налоги ФОТ
C9: Закуп сырья | D9: Кредиторка по аренде | H9: Официанты
C10: Зарплата | D10: Кредиторка по рекламе | H10: Транспортные услуги
D11: Кредиторка по сырью | H11: Транспортные расходы
H12: Фриланс
A13: Непостоянные платежи
B14: Прочее | C14: Расходы персонала | D14: Гос платежи | E14: Подрядчики | F14: Непредвиденные расходы
B15: ОС и ТМЦ | C15: Спецодежда | D15: Участие на тендерах | E15: Административные подрядчики
B16: Содержание объектов | C16: Канцтовары | D16: Платежи в бюджет | E16: Услуги сторонних подрядчиков
B17: Стратсессии | C17: Командировочные | D17: Производственный контроль (СЭС) | E17: Производственные подрядчики
C18: Медосмотры
C19: Представительские расходы
C20: Поиск и найм персонала

Sheet Сопоставление
A1: Названия в финтабло | C1: Название в таблице фондов
A2: Статья | B2: Род. статья
A3: Агентские вознаграждения | C3: Агентские вознаграждения
A4: Агрегаторы | C4: Агрегаторы
A5: Административные подрядчики | C5: Административные подрядчики
A6: Банковское обслуживание | C6: Банковское обслуживание
A7: Возврат клиентам | C7: Возврат клиентам
A8: Вывод прибыли | C8: Вывод прибыли (дивиденды)
A9: Закуп сырья | C9: Закуп сырья
A10: Вспомогательное сырье | B10: Закуп сырья | C10: Закуп сырья
A11: Основное сырье | B11: Закуп сырья | C11: Закуп сырья
A12: Сырье за наличные/бизнес карту | B12: Закуп сырья | C12: Закуп сырья
A13: Зарплата | C13: Зарплата
A14: Аванс | B14: Зарплата | C14: Зарплата
A15: Займ в счет зарплаты | B15: Зарплата | C15: Зарплата
A16: Зарплата | B16: Зарплата | C16: Зарплата
A17: Зарплата основная | B17: Зарплата | C17: Зарплата
A18: Отпускные | B18: Зарплата | C18: Зарплата
A19: Расчет при увольнении | B19: Зарплата | C19: Зарплата
A20: Фрилансы | B20: Зарплата | C20: Зарплата
A21: Канцтовары | C21: Канцтовары
A22: Командировочные расходы | C22: Командировочные
A23: Комиссия по эквайрингу | C23: Комиссия по эквайрингу
A24: Медосмотр и прививки | C24: Медосмотры
A25: Налоги на доходы (прибыль) | C25: Налог на доходы
A26: Налоги за сотрудников | C26: Налог ФОТ
A27: Взносы в фонды | B27: Налоги за сотрудников | C27: Налог ФОТ
A28: НДФЛ | B28: Налоги за сотрудников | C28: Налог ФОТ
A29: Неучтенные расходы | C29: Непредвиденные расходы
A30: Аренда гаража | C30: Оплата аренды и ВКУ
A31: Аренда объектов | C31: Оплата аренды и ВКУ
A32: Аренда объектов | B32: Аренда объектов | C32: Оплата аренды и ВКУ
A33: Аренда офиса | B33: Аренда объектов | C33: Оплата аренды и ВКУ
A34: Коммунальные расходы | B34: Аренда объектов | C34: Оплата аренды и ВКУ
A35: Официанты | C35: Официанты
A36: Платежи в бюджет | C36: Платежи в бюджет
A37: Выплата тела кредита | C37: Погашение кредитов
A38: Проценты по кредиту | C38: Погашение кредитов
A39: Поиск и найм персонала | C39: Поиск и найм персонала
A40: Представительские расходы | C40: Представительские расходы
...

Sheet Сотношение
A1: Группа | B1: Направление | C1: Статья | D1: Род Статья
A2: Агентские вознаграждения | C2: Агентские вознаграждения
A3: Агрегаторы | C3: Агрегаторы
B4: Киви Фит | C4: Агрегаторы
A5: Банковское обслуживание | C5: Банковское обслуживание
A6: Комиссия по эквайрингу | C6: Комиссия по эквайрингу
B7: Кафе Вилюйск | C7: Комиссия по эквайрингу
A8: Налог на доходы
A9: Налог ФОТ
A10: Оплата аренды и ВКУ
A11: Погашение кредитов
A12: Расходы на программное обеспечение | C12: Расходы на программное обеспечение
B13: Кейтеринг | C13: Расходы на программное обеспечение
A14: Топливо | C14: Топливо
B15: Кафе Вилюйск | C15: Топливо
A16: Услуги связи и интернета | C16: Услуги связи и интернета
B17: Кафе Вилюйск | C17: Услуги связи и интернета
B18: Кейтеринг | C18: Услуги связи и интернета
B19: Офис Вилюйский тракт | C19: Услуги связи и интернета
A20: Услуги такси/Развоз персонала
A22: Возврат клиентам | C22: Возврат клиентам
B23: Айыы кыьата | C23: Возврат клиентам
B24: Кафе Вилюйск | C24: Возврат клиентам
B25: СОШ № 21 | C25: Возврат клиентам
B26: СОШ № 26 | C26: Возврат клиентам
B27: СОШ № 7 | C27: Возврат клиентам
A28: Вывод прибыли (дивиденды) | C28: Вывод прибыли
A29: Закуп сырья | C29: Вспомогательное сырье | D29: Закуп сырья
C30: Основное сырье | D30: Закуп сырья
C31: Сырье за наличные/бизнес карту | D31: Закуп сырья
B32: Айыы кыьата | C32: Сырье за наличные/бизнес карту | D32: Закуп сырья
B33: КТФ | C33: Основное сырье | D33: Закуп сырья
B34: Кафе Вилюйск | C34: Сырье за наличные/бизнес карту | D34: Закуп сырья
B35: Кейтеринг | C35: Вспомогательное сырье | D35: Закуп сырья
B36: РЦ | C36: Основное сырье | D36: Закуп сырья
A37: Зарплата | C37: Аванс | D37: Зарплата
C38: Зарплата основная | D38: Зарплата
C39: Отпускные | D39: Зарплата
C40: Расчет при увольнении | D40: Зарплата
C41: Фрилансы | D41: Зарплата
...

Sheet Лист2
A1: Аванс | B1: {=IFERROR(INDEX($F$1:$F$140,MATCH(A1,'Сотношение'!$C$1:$C$140,0)),IFERROR(INDEX($F$1:$F$140,MATCH(A1,$F$1:$F$140,0)),"НЕ НАЙДЕНО"))} -> Зарплата | F1: {=SCAN("",'Сотношение'!A1:A140,LAMBDA(acc,cur,IF(cur<>"",cur,acc)))} -> Группа
A2: Агентские вознаграждения | B2: {=IFERROR(INDEX($F$1:$F$140,MATCH(A2,'Сотношение'!$C$1:$C$140,0)),IFERROR(INDEX($F$1:$F$140,MATCH(A2,$F$1:$F$140,0)),"НЕ НАЙДЕНО"))} -> Агентские вознаграждения | F2: Агентские вознаграждения
A3: Агрегаторы | B3: {=IFERROR(INDEX($F$1:$F$140,MATCH(A3,'Сотношение'!$C$1:$C$140,0)),IFERROR(INDEX($F$1:$F$140,MATCH(A3,$F$1:$F$140,0)),"НЕ НАЙДЕНО"))} -> Агрегаторы | F3: Агрегаторы
A4: Административные подрядчики | B4: {=IFERROR(INDEX($F$1:$F$140,MATCH(A4,'Сотношение'!$C$1:$C$140,0)),IFERROR(INDEX($F$1:$F$140,MATCH(A4,$F$1:$F$140,0)),"НЕ НАЙДЕНО"))} -> Административные подрядчики | F4: Агрегаторы
A5: Аренда объектов | B5: {=IFERROR(INDEX($F$1:$F$140,MATCH(A5,'Сотношение'!$C$1:$C$140,0)),IFERROR(INDEX($F$1:$F$140,MATCH(A5,$F$1:$F$140,0)),"НЕ НАЙДЕНО"))} -> НЕ НАЙДЕНО | F5: Банковское обслуживание
A6: Банковское обслуживание | B6: {=IFERROR(INDEX($F$1:$F$140,MATCH(A6,'Сотношение'!$C$1:$C$140,0)),IFERROR(INDEX($F$1:$F$140,MATCH(A6,$F$1:$F$140,0)),"НЕ НАЙДЕНО"))} -> Банковское обслуживание | F6: Комиссия по эквайрингу
A7: Больничные | B7: {=IFERROR(INDEX($F$1:$F$140,MATCH(A7,'Сотношение'!$C$1:$C$140,0)),IFERROR(INDEX($F$1:$F$140,MATCH(A7,$F$1:$F$140,0)),"НЕ НАЙДЕНО"))} -> НЕ НАЙДЕНО | F7: Комиссия по эквайрингу
A8: Бюджет на трафик | B8: {=IFERROR(INDEX($F$1:$F$140,MATCH(A8,'Сотношение'!$C$1:$C$140,0)),IFERROR(INDEX($F$1:$F$140,MATCH(A8,$F$1:$F$140,0)),"НЕ НАЙДЕНО"))} -> Рекламный бюджет | F8: Налог на доходы
A9: Взносы в фонды | B9: {=IFERROR(INDEX($F$1:$F$140,MATCH(A9,'Сотношение'!$C$1:$C$140,0)),IFERROR(INDEX($F$1:$F$140,MATCH(A9,$F$1:$F$140,0)),"НЕ НАЙДЕНО"))} -> НЕ НАЙДЕНО | F9: Налог ФОТ
A10: Возврат внесенных средств собственника | B10: {=IFERROR(INDEX($F$1:$F$140,MATCH(A10,'Сотношение'!$C$1:$C$140,0)),IFERROR(INDEX($F$1:$F$140,MATCH(A10,$F$1:$F$140,0)),"НЕ НАЙДЕНО"))} -> НЕ НАЙДЕНО | F10: Оплата аренды и ВКУ
A11: Возврат клиентам | B11: {=IFERROR(INDEX($F$1:$F$140,MATCH(A11,'Сотношение'!$C$1:$C$140,0)),IFERROR(INDEX($F$1:$F$140,MATCH(A11,$F$1:$F$140,0)),"НЕ НАЙДЕНО"))} -> Возврат клиентам | F11: Погашение кредитов
A12: Вспомогательное сырье | B12: {=IFERROR(INDEX($F$1:$F$140,MATCH(A12,'Сотношение'!$C$1:$C$140,0)),IFERROR(INDEX($F$1:$F$140,MATCH(A12,$F$1:$F$140,0)),"НЕ НАЙДЕНО"))} -> Закуп сырья | F12: Расходы на программное обеспечение
A13: Вывод прибыли | B13: {=IFERROR(INDEX($F$1:$F$140,MATCH(A13,'Сотношение'!$C$1:$C$140,0)),IFERROR(INDEX($F$1:$F$140,MATCH(A13,$F$1:$F$140,0)),"НЕ НАЙДЕНО"))} -> Вывод прибыли (дивиденды) | F13: Расходы на программное обеспечение
... A49: Фрилансы | B49: {=IFERROR(INDEX($F$1:$F$140,MATCH(A49,'Сотношение'!$C$1:$C$140,0)),IFERROR(INDEX($F$1:$F$140,MATCH(A49,$F$1:$F$140,0)),"НЕ НАЙДЕНО"))} -> Зарплата | F49: Зарплата
A50: Экспедиционные услуги | F50: Зарплата
F51: Зарплата
F52: Зарплата
F53: Зарплата
F54: Зарплата
F55: Зарплата
F56: Зарплата
F57: Зарплата
F58: Зарплата
F59: Зарплата
F60: Зарплата
F61: Зарплата
F62: Зарплата
... F140: Непредвиденные расходы
